Workbook

Sheet Roadmap
A1: EHS Project Roadmap — Sumter, SC
A2: Prepared by Charlie Ball for Kate Fowler · priorities 1-6 as assigned 31-Jul-2026 · targets run through Q2 2027
A3: HOW TO USE: Column I is yours — add milestones, dates or comments there. Columns A-H are maintained by Charlie; Status (F) updates at each 1:1. Yellow = your input.
A4: Dates are working targets, not committed dates. Anything already past its date shows Status = Overdue. D1 Ref is the task or knowledge ID in the EHS command centre.
A6: Pri | B6: Workstream | C6: Milestone / Deliverable | D6: Owner | E6: Target Date | F6: Status | G6: D1 Ref | H6: Dependency / Note | I6: Kate — Milestone or Comment
A7: 1 | B7: Respirators | C7: Reschedule respirator inspection session | D7: Charlie | E7: 46248 | F7: In progress | G7: #737 | I7: e.g. Gate review with Laura — 15-Sep
A8: 1 | B8: Respirators | C8: Semi-annual respirator inspection & cleaning | D8: Charlie | E8: 46295 | F8: Not started | G8: #470 | H8: Benchmark compliance item
A9: 1 | B9: Respirators | C9: Respirator TPM / cleaning schedule confirmed in place | D9: Charlie | E9: 46295 | F9: Not started | G9: #626
A10: 1 | B10: Respirators | C10: NIOSH 25/26/27 forms organised into folders | D10: Charlie | E10: 46325 | F10: Not started | G10: #488
A11: 1 | B11: Respirators | C11: Respiratory protection program annual review documented | D11: Charlie | E11: 46356 | F11: Not started | G11: #523 | H11: Rides the MESH element review
A12: 1 | B12: Respirators | C12: 2027 cycle scheduled + program closed out | D12: Charlie | E12: 46416 | F12: Not started
A13: 2 | B13: Scrap Bin Standardization | C13: Walk scrap process with Kate, Jad, Ashwin | D13: Charlie | E13: 46255 | F13: Not started | G13: #525 | H13: Prerequisite to back-plate design
A14: 2 | B14: Scrap Bin Standardization | C14: Scrap-bin back plate designed | D14: Charlie / Ashwin | E14: 46290 | F14: Not started | G14: #525 | H14: Bins rotate off 2nd rotator; plate removes manual dumping
A15: 2 | B15: Scrap Bin Standardization | C15: Back plate fabricated + trialled | D15: ATS / Ashwin | E15: 46325 | F15: Not started | G15: #525
A16: 2 | B16: Scrap Bin Standardization | C16: Gray / blue cart standard defined (5S+ shed) | D16: Charlie | E16: 46325 | F16: Not started
A17: 2 | B17: Scrap Bin Standardization | C17: Scrap-band standardization | D17: Charlie | E17: 46356 | F17: Not started | G17: #524 | H17: One of the 5 roadmap risk-reduction projects
A18: 2 | B18: Scrap Bin Standardization | C18: Station cards issued for scrap handling | D18: Charlie | E18: 46444 | F18: Not started | G18: #524
A19: 2 | B19: Scrap Bin Standardization | C19: Standard rolled to all fab areas | D19: Charlie | E19: 46477 | F19: Not started
A20: 3 | B20: Lifting Devices | C20: Vacuum lift solenoid project complete + GHG updated | D20: Charlie | E20: 46248 | F20: Overdue | G20: #691 | H20: Benchmark #162, closure was 31-Jul-2026
A21: 3 | B21: Lifting Devices | C21: Crane inspections — Engineered Systems Inc | D21: Kate | E21: 46265 | F21: In progress | G21: #616 | H21: Kate gathering cost for corporate across sites
A22: 3 | B22: Lifting Devices | C22: Q3 CapEx ~$250k received | D22: Kate | E22: 46265 | F22: In progress | G22: KN #467 | H22: Budget gate for every purchase below
A23: 3 | B23: Lifting Devices | C23: Crane copper lifting devices — implementation plan | D23: Charlie | E23: 46262 | F23: In progress | G23: #696
A24: 3 | B24: Lifting Devices | C24: Replacements specified + quoted | D24: Charlie / Kate | E24: 46283 | F24: Not started | G24: KN #467 | H24: Sheet lifter by paint line + 3 others + big-door lifter lasers to conveyors
A25: 3 | B25: Lifting Devices | C25: PO placed / 10% down | D25: Kate | E25: 46295 | F25: Not started | H25: 10% down locks the project permanently
A26: 3 | B26: Lifting Devices | C26: Crane inspection checklist verified for under-hook devices | D26: Charlie | E26: 46295 | F26: Not started | G26: #309 | H26: Badger lesson learned — 27-stitch laceration
A27: 3 | B27: Lifting Devices | C27: Overhead crane PM ownership resolved | D27: Charlie / Kate / Gireesh | E27: 46325 | F27: Not started | G27: KN #442 | H27: Disputed between supply chain and fab; no PM owner
A28: 3 | B28: Lifting Devices | C28: Setup-frame crane retired, A-frame replaced | D28: Kate | E28: 46353 | F28: Not started | G28: KN #407 | H28: IES spare motor + parts; Hodges shipment held
A29: 3 | B29: Lifting Devices | C29: Yellow gym-hoist training documented in setup | D29: Charlie / Marcus | E29: 46353 | F29: Not started | G29: #618
A30: 3 | B30: Lifting Devices | C30: New lifting devices delivered + installed | D30: Charlie | E30: 46477 | F30: Not started | H30: Lead time dependent on Sep PO
A31: 3 | B31: Lifting Devices | C31: Post-install verification + WSRA updates | D31: Charlie | E31: 46507 | F31: Not started
A32: 4 | B32: Press Brakes | C32: Press-brake safety alert (proper tool use) sent + confirmed | D32: Charlie | E32: 46241 | F32: In progress | G32: #687
A33: 4 | B33: Press Brakes | C33: Dept-wide comm: tools, or no hands on press brakes | D33: Charlie | E33: 46241 | F33: Overdue | G33: #561 / #653
A34: 4 | B34: Press Brakes | C34: Operator safety talk-down run | D34: Charlie | E34: 46248 | F34: Overdue | G34: #654
A35: 4 | B35: Press Brakes | C35: Formal near-miss record opened + Ashwin meeting | D35: Charlie / Ashwin | E35: 46248 | F35: Not started | G35: #623
A36: 4 | B36: Press Brakes | C36: Method sheet updated for changing dies | D36: Charlie | E36: 46255 | F36: Overdue | G36: #690
A37: 4 | B37: Press Brakes | C37: High-risk part population defined + safe routing method | D37: Charlie / Ashwin | E37: 46276 | F37: Not started | G37: #664 | H37: Gates the routing milestone below
A38: 4 | B38: Press Brakes | C38: Press-brake training package built | D38: Charlie | E38: 46295 | F38: Not started | G38: #660 | H38: Ron Brown / Marty Honey
A39: 4 | B39: Press Brakes | C39: AI camera / vision system specified + ordered | D39: Charlie / Ashwin | E39: 46325 | F39: Not started | G39: #521 | H39: Needs Q3 CapEx confirmed
A40: 4 | B40: Press Brakes | C40: HRPs routed through the 4 safe press brakes + Amada | D40: Charlie / Ashwin | E40: 46356 | F40: Not started | G40: #521 | H40: See Assumptions tab — definition of done
A41: 4 | B41: Press Brakes | C41: New-equipment safety standard written | D41: Charlie | E41: 46356 | F41: Not started | G41: #521 | H41: Sumter leads this corporately
...

Sheet Summary
A1: Roadmap Summary
A2: All figures calculated from the Roadmap tab — they update as Status changes.
A4: Pri | B4: Workstream | C4: Milestones | D4: Complete | E4: In progress | F4: Overdue | G4: Not started | H4: % Complete | I4: Last target date
A5: 1 | B5: Respirators | C5: 6 | D5: =COUNTIF(Roadmap!$F$7:$F$12,"Complete") | E5: =COUNTIF(Roadmap!$F$7:$F$12,"In progress") | F5: =COUNTIF(Roadmap!$F$7:$F$12,"Overdue") | G5: =COUNTIF(Roadmap!$F$7:$F$12,"Not started") | H5: =IF($C5=0,0,$D5/$C5) | I5: =MAX(Roadmap!$E$7:$E$12)
A6: 2 | B6: Scrap Bin Standardization | C6: 7 | D6: =COUNTIF(Roadmap!$F$13:$F$19,"Complete") | E6: =COUNTIF(Roadmap!$F$13:$F$19,"In progress") | F6: =COUNTIF(Roadmap!$F$13:$F$19,"Overdue") | G6: =COUNTIF(Roadmap!$F$13:$F$19,"Not started") | H6: =IF($C6=0,0,$D6/$C6) | I6: =MAX(Roadmap!$E$13:$E$19)
A7: 3 | B7: Lifting Devices | C7: 12 | D7: =COUNTIF(Roadmap!$F$20:$F$31,"Complete") | E7: =COUNTIF(Roadmap!$F$20:$F$31,"In progress") | F7: =COUNTIF(Roadmap!$F$20:$F$31,"Overdue") | G7: =COUNTIF(Roadmap!$F$20:$F$31,"Not started") | H7: =IF($C7=0,0,$D7/$C7) | I7: =MAX(Roadmap!$E$20:$E$31)
A8: 4 | B8: Press Brakes | C8: 12 | D8: =COUNTIF(Roadmap!$F$32:$F$43,"Complete") | E8: =COUNTIF(Roadmap!$F$32:$F$43,"In progress") | F8: =COUNTIF(Roadmap!$F$32:$F$43,"Overdue") | G8: =COUNTIF(Roadmap!$F$32:$F$43,"Not started") | H8: =IF($C8=0,0,$D8/$C8) | I8: =MAX(Roadmap!$E$32:$E$43)
A9: 5 | B9: Laceration Risks | C9: 9 | D9: =COUNTIF(Roadmap!$F$44:$F$52,"Complete") | E9: =COUNTIF(Roadmap!$F$44:$F$52,"In progress") | F9: =COUNTIF(Roadmap!$F$44:$F$52,"Overdue") | G9: =COUNTIF(Roadmap!$F$44:$F$52,"Not started") | H9: =IF($C9=0,0,$D9/$C9) | I9: =MAX(Roadmap!$E$44:$E$52)
A10: 6 | B10: Laser Loading | C10: 6 | D10: =COUNTIF(Roadmap!$F$53:$F$58,"Complete") | E10: =COUNTIF(Roadmap!$F$53:$F$58,"In progress") | F10: =COUNTIF(Roadmap!$F$53:$F$58,"Overdue") | G10: =COUNTIF(Roadmap!$F$53:$F$58,"Not started") | H10: =IF($C10=0,0,$D10/$C10) | I10: =MAX(Roadmap!$E$53:$E$58)
B11: TOTAL | C11: =SUM(C5:C10) | D11: =SUM(D5:D10) | E11: =SUM(E5:E10) | F11: =SUM(F5:F10) | G11: =SUM(G5:G10) | H11: =IF($C11=0,0,$D11/$C11) | I11: =MAX(Roadmap!$E$7:$E$58)
B13: Counts read Status on the Roadmap tab; % Complete = Complete / Milestones. Update Status there and these refresh.

Sheet Assumptions & Open Items
A1: Assumptions and Open Items
A2: These drive the dates on the Roadmap tab. If an assumption is wrong the dates move — flag it and I will reissue.
A4: # | B4: Item | C4: Assumption made | D4: What I need from you
A5: 1 | B5: Press brakes — definition of done | C5: I have taken 'done' to mean all three: high-risk parts identified and routed through the 4 safe press brakes and the Amada, the AI camera system installed and validated, and the new-equipment standard written. Routing and the standard land in 2026; camera install runs into Q1 2027 on lead time. | D5: Confirm this is the finish line you have in mind, or tell me which of the three you are dating.
A6: 2 | B6: Laser loading vs 2027 divestiture | C6: Two suppliers are buying the lasers, punches and spot welders as Sumter moves to switchboard-only in 2027 (KN #416). I have scoped Laser 2 and 3 loading mods as conditional and put a scope-confirmation gate in September before any spend. | D6: Whether we invest in loading mods for assets that leave in 2027, or hold at controls and training only.
A7: 3 | B7: Q3 CapEx gate | C7: Lifting device purchases and the AI camera order both assume the ~$250k Q3 CapEx lands in August as planned. PO placed September with 10% down to lock it. | D7: Confirm the August timing and whether the AI camera comes out of this pot or a separate one.
A8: 4 | B8: Respirators scope | C8: Treated as a compliance-maintenance workstream, not a build — inspection cadence, TPM schedule, forms and the annual program review. No new respirator selection or fit-test program assumed. | D8: Confirm nothing larger is intended here.
A9: 5 | B9: Owner assignments | C9: Where a task had no owner in the system I have put myself. Ashwin carries the engineering reviews, ATS the fabrication and install. | D9: Correct anything I have assigned to the wrong person.
A10: 6 | B10: Overdue items | C10: Five items were already past their date at issue and are dated forward into August: vacuum lift solenoid (Benchmark #162), the two press-brake communications, the operator talk-down and the die-change method sheet. | D10: No action needed — flagging so the red on the sheet is not a surprise.
A11: 7 | B11: Dates are targets | C11: Working targets for sequencing and 1:1 review, not committed dates to corporate. Nothing here has been shared outside the two of us. | D11: Tell me which of these you want turned into committed dates.
